Workbook

Sheet Calc
A1: Calculations feeding the Dashboard (Completed orders only for sales figures)
A3: By product
A4: Label | B4: Net sales (EGP) | C4: Completed orders
A5: Headphones | B5: =SUMIFS(Cleaned_Data!$N:$N,Cleaned_Data!$E:$E,$A5,Cleaned_Data!$L:$L,"Completed") -> 32058.496 | C5: =COUNTIFS(Cleaned_Data!$E:$E,$A5,Cleaned_Data!$L:$L,"Completed") -> 17
A6: Backpack | B6: =SUMIFS(Cleaned_Data!$N:$N,Cleaned_Data!$E:$E,$A6,Cleaned_Data!$L:$L,"Completed") -> 29689.491 | C6: =COUNTIFS(Cleaned_Data!$E:$E,$A6,Cleaned_Data!$L:$L,"Completed") -> 27
A7: Desk Lamp | B7: =SUMIFS(Cleaned_Data!$N:$N,Cleaned_Data!$E:$E,$A7,Cleaned_Data!$L:$L,"Completed") -> 21851.793 | C7: =COUNTIFS(Cleaned_Data!$E:$E,$A7,Cleaned_Data!$L:$L,"Completed") -> 27
A8: Keyboard | B8: =SUMIFS(Cleaned_Data!$N:$N,Cleaned_Data!$E:$E,$A8,Cleaned_Data!$L:$L,"Completed") -> 21558.457 | C8: =COUNTIFS(Cleaned_Data!$E:$E,$A8,Cleaned_Data!$L:$L,"Completed") -> 15
A9: Water Bottle | B9: =SUMIFS(Cleaned_Data!$N:$N,Cleaned_Data!$E:$E,$A9,Cleaned_Data!$L:$L,"Completed") -> 6758.1395 | C9: =COUNTIFS(Cleaned_Data!$E:$E,$A9,Cleaned_Data!$L:$L,"Completed") -> 21
A10: Wireless Mouse | B10: =SUMIFS(Cleaned_Data!$N:$N,Cleaned_Data!$E:$E,$A10,Cleaned_Data!$L:$L,"Completed") -> 5622.66 | C10: =COUNTIFS(Cleaned_Data!$E:$E,$A10,Cleaned_Data!$L:$L,"Completed") -> 11
A11: Phone Stand | B11: =SUMIFS(Cleaned_Data!$N:$N,Cleaned_Data!$E:$E,$A11,Cleaned_Data!$L:$L,"Completed") -> 4684.145 | C11: =COUNTIFS(Cleaned_Data!$E:$E,$A11,Cleaned_Data!$L:$L,"Completed") -> 18
A12: USB-C Cable | B12: =SUMIFS(Cleaned_Data!$N:$N,Cleaned_Data!$E:$E,$A12,Cleaned_Data!$L:$L,"Completed") -> 3704.9365 | C12: =COUNTIFS(Cleaned_Data!$E:$E,$A12,Cleaned_Data!$L:$L,"Completed") -> 20
A13: Pen Set | B13: =SUMIFS(Cleaned_Data!$N:$N,Cleaned_Data!$E:$E,$A13,Cleaned_Data!$L:$L,"Completed") -> 2444.141 | C13: =COUNTIFS(Cleaned_Data!$E:$E,$A13,Cleaned_Data!$L:$L,"Completed") -> 17
A14: Notebook | B14: =SUMIFS(Cleaned_Data!$N:$N,Cleaned_Data!$E:$E,$A14,Cleaned_Data!$L:$L,"Completed") -> 2119.342 | C14: =COUNTIFS(Cleaned_Data!$E:$E,$A14,Cleaned_Data!$L:$L,"Completed") -> 20
A17: By city
A18: Label | B18: Net sales (EGP) | C18: Completed orders
A19: Giza | B19: =SUMIFS(Cleaned_Data!$N:$N,Cleaned_Data!$D:$D,$A19,Cleaned_Data!$L:$L,"Completed") -> 31587.162 | C19: =COUNTIFS(Cleaned_Data!$D:$D,$A19,Cleaned_Data!$L:$L,"Completed") -> 44
A20: Aswan | B20: =SUMIFS(Cleaned_Data!$N:$N,Cleaned_Data!$D:$D,$A20,Cleaned_Data!$L:$L,"Completed") -> 21340.656 | C20: =COUNTIFS(Cleaned_Data!$D:$D,$A20,Cleaned_Data!$L:$L,"Completed") -> 33
A21: Mansoura | B21: =SUMIFS(Cleaned_Data!$N:$N,Cleaned_Data!$D:$D,$A21,Cleaned_Data!$L:$L,"Completed") -> 20239.9 | C21: =COUNTIFS(Cleaned_Data!$D:$D,$A21,Cleaned_Data!$L:$L,"Completed") -> 35
A22: Tanta | B22: =SUMIFS(Cleaned_Data!$N:$N,Cleaned_Data!$D:$D,$A22,Cleaned_Data!$L:$L,"Completed") -> 19703.739 | C22: =COUNTIFS(Cleaned_Data!$D:$D,$A22,Cleaned_Data!$L:$L,"Completed") -> 27
A23: Cairo | B23: =SUMIFS(Cleaned_Data!$N:$N,Cleaned_Data!$D:$D,$A23,Cleaned_Data!$L:$L,"Completed") -> 18596.392 | C23: =COUNTIFS(Cleaned_Data!$D:$D,$A23,Cleaned_Data!$L:$L,"Completed") -> 26
A24: Alexandria | B24: =SUMIFS(Cleaned_Data!$N:$N,Cleaned_Data!$D:$D,$A24,Cleaned_Data!$L:$L,"Completed") -> 18497.05 | C24: =COUNTIFS(Cleaned_Data!$D:$D,$A24,Cleaned_Data!$L:$L,"Completed") -> 25
A25: Unknown | B25: =SUMIFS(Cleaned_Data!$N:$N,Cleaned_Data!$D:$D,$A25,Cleaned_Data!$L:$L,"Completed") -> 526.701 | C25: =COUNTIFS(Cleaned_Data!$D:$D,$A25,Cleaned_Data!$L:$L,"Completed") -> 3
A28: By category
A29: Label | B29: Net sales (EGP) | C29: Completed orders | D29: Share of net sales
A30: Electronics | B30: =SUMIFS(Cleaned_Data!$N:$N,Cleaned_Data!$F:$F,$A30,Cleaned_Data!$L:$L,"Completed") -> 62944.549 | C30: =COUNTIFS(Cleaned_Data!$F:$F,$A30,Cleaned_Data!$L:$L,"Completed") -> 63 | D30: =IFERROR(B30/SUMIFS(Cleaned_Data!$N:$N,Cleaned_Data!$L:$L,"Completed"),0) -> 0.48236475
A31: Accessories | B31: =SUMIFS(Cleaned_Data!$N:$N,Cleaned_Data!$F:$F,$A31,Cleaned_Data!$L:$L,"Completed") -> 34373.636 | C31: =COUNTIFS(Cleaned_Data!$F:$F,$A31,Cleaned_Data!$L:$L,"Completed") -> 45 | D31: =IFERROR(B31/SUMIFS(Cleaned_Data!$N:$N,Cleaned_Data!$L:$L,"Completed"),0) -> 0.26341646
A32: Home & Kitchen | B32: =SUMIFS(Cleaned_Data!$N:$N,Cleaned_Data!$F:$F,$A32,Cleaned_Data!$L:$L,"Completed") -> 28609.933 | C32: =COUNTIFS(Cleaned_Data!$F:$F,$A32,Cleaned_Data!$L:$L,"Completed") -> 48 | D32: =IFERROR(B32/SUMIFS(Cleaned_Data!$N:$N,Cleaned_Data!$L:$L,"Completed"),0) -> 0.21924731
A33: Stationery | B33: =SUMIFS(Cleaned_Data!$N:$N,Cleaned_Data!$F:$F,$A33,Cleaned_Data!$L:$L,"Completed") -> 4563.483 | C33: =COUNTIFS(Cleaned_Data!$F:$F,$A33,Cleaned_Data!$L:$L,"Completed") -> 37 | D33: =IFERROR(B33/SUMIFS(Cleaned_Data!$N:$N,Cleaned_Data!$L:$L,"Completed"),0) -> 0.034971469
A36: By sales channel
A37: Label | B37: Net sales (EGP) | C37: Share of net sales
A38: Facebook | B38: =SUMIFS(Cleaned_Data!$N:$N,Cleaned_Data!$J:$J,$A38,Cleaned_Data!$L:$L,"Completed") -> 39598.178 | C38: =IFERROR(B38/SUMIFS(Cleaned_Data!$N:$N,Cleaned_Data!$L:$L,"Completed"),0) -> 0.30345384
A39: Online | B39: =SUMIFS(Cleaned_Data!$N:$N,Cleaned_Data!$J:$J,$A39,Cleaned_Data!$L:$L,"Completed") -> 35935.888 | C39: =IFERROR(B39/SUMIFS(Cleaned_Data!$N:$N,Cleaned_Data!$L:$L,"Completed"),0) -> 0.27538851
A40: WhatsApp | B40: =SUMIFS(Cleaned_Data!$N:$N,Cleaned_Data!$J:$J,$A40,Cleaned_Data!$L:$L,"Completed") -> 33044.444 | C40: =IFERROR(B40/SUMIFS(Cleaned_Data!$N:$N,Cleaned_Data!$L:$L,"Completed"),0) -> 0.25323042
A41: Store | B41: =SUMIFS(Cleaned_Data!$N:$N,Cleaned_Data!$J:$J,$A41,Cleaned_Data!$L:$L,"Completed") -> 21913.092 | C41: =IFERROR(B41/SUMIFS(Cleaned_Data!$N:$N,Cleaned_Data!$L:$L,"Completed"),0) -> 0.16792722
A44: By order status (all rows)
A45: Label | B45: Orders | C45: Net value (EGP)
A46: Completed | B46: =COUNTIFS(Cleaned_Data!$L:$L,$A46) -> 193 | C46: =SUMIFS(Cleaned_Data!$N:$N,Cleaned_Data!$L:$L,$A46) -> 130491.6
A47: Cancelled | B47: =COUNTIFS(Cleaned_Data!$L:$L,$A47) -> 71 | C47: =SUMIFS(Cleaned_Data!$N:$N,Cleaned_Data!$L:$L,$A47) -> 41562.343
A48: Returned | B48: =COUNTIFS(Cleaned_Data!$L:$L,$A48) -> 71 | C48: =SUMIFS(Cleaned_Data!$N:$N,Cleaned_Data!$L:$L,$A48) -> 43934.012
A50: Monthly trend (Completed)
...

Sheet DASHBOARD

Sheet Orders_Raw
A1: Order_ID | B1: Order_Date | C1: Customer_Name | D1: City | E1: Product | F1: Category | G1: Quantity | H1: Unit_Price_EGP | I1: Discount_% | J1: Sales_Channel | K1: Payment_Method | L1: Order_Status | M1: Customer_Email
A2: ORD-0001 | B2: 2025-04-25 | C2: Mona Ali | D2: Aswan | E2: USB-C Cable | F2: Electronics | G2: 1 | H2: 116.25 | I2: 15 | J2: Store | K2: Vodafone Cash | L2: Completed | M2: customer9@example.com
A3: ORD-0002 | B3: 2025-01-14 | C3: Sara Mahmoud | D3: Aswan | E3: Wireless Mouse | F3: Electronics | G3: 1 | H3: 335.36 | I3: 15 | J3: WhatsApp | K3: Credit Card | L3: Cancelled | M3: customer115@example.com
A4: ORD-0003 | B4: 2025-03-23 | C4: Nour Khaled | D4: Giza | E4: Headphones | F4: Electronics | G4: 1 | H4: 1061.46 | I4: 0 | J4: Online | K4: Instapay | L4: Returned | M4: customer27@example.com
A5: ORD-0004 | B5: 2025-06-26 | C5: Youssef Adel | D5: Cairo | E5: USB-C Cable | F5: Electronics | G5: 1 | H5: 118.77 | I5: 15 | J5: WhatsApp | K5: Cash | L5: Cancelled | M5: customer97@example.com
A6: ORD-0005 | B6: 2025-07-05 | C6: Sara Mahmoud | D6: Aswan | E6: USB-C Cable | F6: Electronics | G6: 2 | H6: =AVERAGE(H94,H227) -> 127.005 | I6: 0 | J6: Store | K6: Credit Card | L6: Cancelled | M6: customer75@example.com
A7: ORD-0006 | B7: 2025-07-14 | C7: Karim Fathy | D7: Aswan | E7: USB-C Cable | F7: Electronics | G7: 3 | H7: 133.99 | I7: 20 | J7: Facebook | K7: Credit Card | L7: Completed | M7: customer95@example.com
A8: ORD-0007 | B8: 2025-02-06 | C8: Omar Samir | D8: Tanta | E8: Desk Lamp | F8: Home & Kitchen | G8: 1 | H8: 406.03 | I8: 15 | J8: Online | K8: Credit Card | L8: Cancelled | M8: customer119@example.com
A9: ORD-0008 | B9: 2025-04-23 | C9: Ahmed Hassan | D9: Alexandria | E9: Backpack | F9: Accessories | G9: 1 | H9: 38 | I9: 20 | J9: Store | K9: Instapay | L9: Completed | M9: customer103@example.com
A10: ORD-0009 | B10: 2025-06-11 | C10: Karim Fathy | D10: Mansoura | E10: Notebook | F10: Stationery | G10: 1 | H10: 62.06 | I10: 15 | J10: WhatsApp | K10: Credit Card | L10: Completed | M10: customer68@example.com
A11: ORD-0010 | B11: 2025-05-15 | C11: Salma Mostafa | D11: Tanta | E11: Keyboard | F11: Electronics | G11: 1 | H11: 676.22 | I11: 5 | J11: Facebook | K11: Credit Card | L11: Cancelled | M11: customer36@example.com
A12: ORD-0011 | B12: 2025-02-26 | C12: Omar Samir | D12: Unknown | E12: Pen Set | F12: Stationery | G12: 2 | H12: 98.01 | I12: 5 | J12: Store | K12: Vodafone Cash | L12: Completed | M12: customer98@example.com
A13: ORD-0012 | B13: 2025-01-06 | C13: Hana Ibrahim | D13: Giza | E13: Headphones | F13: Electronics | G13: 5 | H13: 980.66 | I13: 20 | J13: Facebook | K13: Cash | L13: Completed | M13: customer76@example.com
A14: ORD-0013 | B14: 2025-05-15 | C14: Omar Samir | D14: Tanta | E14: Backpack | F14: Accessories | G14: 1 | H14: 702.63 | I14: 0 | J14: Facebook | K14: Credit Card | L14: Cancelled | M14: customer40@example.com
A15: ORD-0014 | B15: 2025-09-29 | C15: Ali Mohamed | D15: Giza | E15: Desk Lamp | F15: Home & Kitchen | G15: 3 | H15: 434.63 | I15: 5 | J15: Store | K15: Cash | L15: Completed | M15: customer93@example.com
A16: ORD-0015 | B16: 2025-02-10 | C16: Karim Fathy | D16: Cairo | E16: Notebook | F16: Stationery | G16: 1 | H16: 52.81 | I16: 20 | J16: Online | K16: Credit Card | L16: Completed | M16: customer122@example.com
A17: ORD-0016 | B17: 2025-08-05 | C17: Hana Ibrahim | D17: Aswan | E17: Pen Set | F17: Stationery | G17: 1 | H17: 92.87 | I17: 15 | J17: Online | K17: Instapay | L17: Completed | M17: customer103@example.com
A18: ORD-0017 | B18: 2025-03-03 | C18: Sara Mahmoud | D18: Cairo | E18: Desk Lamp | F18: Home & Kitchen | G18: 1 | H18: 432.35 | I18: 0 | J18: Store | K18: Credit Card | L18: Completed | M18: customer57@example.com
... A336: ORD-0350 | B336: 2025-07-26 | C336: Sara Mahmoud | D336: Alexandria | E336: Desk Lamp | F336: Home & Kitchen | G336: 2 | H336: 395.31 | I336: 15 | J336: Online | K336: Credit Card | L336: Completed | M336: customer6@example.com

Sheet Project_Guide
A1: Item | B1: Details
A2: Project scenario | B2: A small Egyptian retail business selling electronics, stationery, home goods, and accessories.
A3: Business question | B3: Which products, cities, and sales channels drive revenue, and where are returns/cancellations concentrated?
A4: Suggested Excel tasks | B4: Inspect data quality; standardize dates and labels; handle blanks; identify duplicates and invalid quantities/discounts; calculate Net Sales; build PivotTables and a dashboard.
A5: Important note | B5: The Orders sheet intentionally contains data-quality issues. Keep a copy of the raw sheet before cleaning.
A6: Currency | B6: EGP (Egyptian pounds)
A7: Rows in Orders sheet | B7: 354 records

Sheet PT_Product_Sales
A1: Order_Status | B1: Completed
A3: Product | B3: Sum of Net_Sales_EGP
A4: Headphones | B4: 32058.496
A5: Backpack | B5: 29689.491
A6: Desk Lamp | B6: 21851.793
A7: Keyboard | B7: 21558.457
A8: Water Bottle | B8: 6758.1395
A9: Wireless Mouse | B9: 5622.66
A10: Phone Stand | B10: 4684.145
A11: USB-C Cable | B11: 3704.9365
A12: Pen Set | B12: 2444.141
A13: Notebook | B13: 2119.342
A14: Total Result | B14: 130491.6

Sheet PT_City_Sales
A1: Order_Status | B1: Completed
A3: City | B3: Sum of Net_Sales_EGP
A4: Alexandria | B4: 18497.05
A5: Aswan | B5: 21340.656
A6: Cairo | B6: 18596.392
A7: Giza | B7: 31587.162
A8: Mansoura | B8: 20239.9
A9: Tanta | B9: 19703.739
A10: Unknown | B10: 526.701
A11: Total Result | B11: 130491.6

Sheet PT_Category_Sales
A1: Order_Status | B1: Completed
A3: Category | B3: Sum of Net_Sales_EGP
A4: Accessories | B4: 34373.636
A5: Electronics | B5: 62944.549
A6: Home & Kitchen | B6: 28609.933
A7: Stationery | B7: 4563.483
A8: Total Result | B8: 130491.6

Sheet PT_Channel_Sales
A1: Order_Status | B1: Completed
A3: Sales_Channel | B3: Sum of Net_Sales_EGP
A4: Facebook | B4: 39598.178
A5: Online | B5: 35935.888
A6: Store | B6: 21913.091
A7: WhatsApp | B7: 33044.444
A8: Total Result | B8: 130491.6

Sheet PT_Order_Status
A1: Order Status Analysis
A3: Order_Status | B3: Count of Order_ID
A4: Cancelled | B4: 71
A5: Completed | B5: 193
A6: Returned | B6: 71
A7: Total Result | B7: 335

Sheet Cleaned_Data
A1: Order_ID | B1: Order_Date | C1: Customer_Name | D1: City | E1: Product | F1: Category | G1: Quantity | H1: Unit_Price_EGP | I1: Discount_% | J1: Sales_Channel | K1: Payment_Method | L1: Order_Status | M1: Customer_Email | N1: Net_Sales_EGP | P1: Charts (live, from Calc)
A2: ORD-0001 | B2: 45772 | C2: Mona Ali | D2: Aswan | E2: USB-C Cable | F2: Electronics | G2: 1 | H2: 116.25 | I2: 15 | J2: Store | K2: Vodafone Cash | L2: Completed | M2: customer9@example.com | N2: 98.8125
A3: ORD-0002 | B3: 45671 | C3: Sara Mahmoud | D3: Aswan | E3: Wireless Mouse | F3: Electronics | G3: 1 | H3: 335.36 | I3: 15 | J3: WhatsApp | K3: Credit Card | L3: Cancelled | M3: customer115@example.com | N3: 285.056
A4: ORD-0003 | B4: 45739 | C4: Nour Khaled | D4: Giza | E4: Headphones | F4: Electronics | G4: 1 | H4: 1061.46 | I4: 0 | J4: Online | K4: Instapay | L4: Returned | M4: customer27@example.com | N4: 1061.46
A5: ORD-0004 | B5: 45834 | C5: Youssef Adel | D5: Cairo | E5: USB-C Cable | F5: Electronics | G5: 1 | H5: 118.77 | I5: 15 | J5: WhatsApp | K5: Cash | L5: Cancelled | M5: customer97@example.com | N5: 100.9545
A6: ORD-0005 | B6: 45843 | C6: Sara Mahmoud | D6: Aswan | E6: USB-C Cable | F6: Electronics | G6: 2 | H6: 127.005 | I6: 0 | J6: Store | K6: Credit Card | L6: Cancelled | M6: customer75@example.com | N6: 254.01
A7: ORD-0006 | B7: 45852 | C7: Karim Fathy | D7: Aswan | E7: USB-C Cable | F7: Electronics | G7: 3 | H7: 133.99 | I7: 20 | J7: Facebook | K7: Credit Card | L7: Completed | M7: customer95@example.com | N7: 321.576
A8: ORD-0007 | B8: 45694 | C8: Omar Samir | D8: Tanta | E8: Desk Lamp | F8: Home & Kitchen | G8: 1 | H8: 406.03 | I8: 15 | J8: Online | K8: Credit Card | L8: Cancelled | M8: customer119@example.com | N8: 345.1255
A9: ORD-0008 | B9: 45770 | C9: Ahmed Hassan | D9: Alexandria | E9: Backpack | F9: Accessories | G9: 1 | H9: 38 | I9: 20 | J9: Store | K9: Instapay | L9: Completed | M9: customer103@example.com | N9: 30.4
A10: ORD-0009 | B10: 45819 | C10: Karim Fathy | D10: Mansoura | E10: Notebook | F10: Stationery | G10: 1 | H10: 62.06 | I10: 15 | J10: WhatsApp | K10: Credit Card | L10: Completed | M10: customer68@example.com | N10: 52.751
A11: ORD-0010 | B11: 45792 | C11: Salma Mostafa | D11: Tanta | E11: Keyboard | F11: Electronics | G11: 1 | H11: 676.22 | I11: 5 | J11: Facebook | K11: Credit Card | L11: Cancelled | M11: customer36@example.com | N11: 642.409
A12: ORD-0011 | B12: 45714 | C12: Omar Samir | D12: Unknown | E12: Pen Set | F12: Stationery | G12: 2 | H12: 98.01 | I12: 5 | J12: Store | K12: Vodafone Cash | L12: Completed | M12: customer98@example.com | N12: 186.219
A13: ORD-0012 | B13: 45663 | C13: Hana Ibrahim | D13: Giza | E13: Headphones | F13: Electronics | G13: 5 | H13: 980.66 | I13: 20 | J13: Facebook | K13: Cash | L13: Completed | M13: customer76@example.com | N13: 3922.64
... A67: ORD-0070 | B67: 45708 | C67: Sara Mahmoud | D67: Giza | E67: Headphones | F67: Electronics | G67: 2 | H67: 999.79 | I67: 15 | J67: Store | K67: Credit Card | L67: Completed | M67: customer62@example.com | N67: 1699.643
A68: ORD-0071 | B68: 13/32/2025 | C68: Ali Mohamed | D68: Mansoura | E68: Keyboard | F68: Electronics | G68: 2 | H68: 610.44 | I68: 0 | J68: Store | K68: Credit Card | L68: Returned | M68: customer74@example.com | N68: 1220.88
A69: ORD-0072 | B69: 45777 | C69: Ali Mohamed | D69: Aswan | E69: Notebook | F69: Stationery | G69: 2 | H69: 55.74 | I69: 20 | J69: Online | K69: Vodafone Cash | L69: Completed | M69: customer30@example.com | N69: 89.184
A70: ORD-0073 | B70: 45794 | C70: Mona Ali | D70: Cairo | E70: Pen Set | F70: Stationery | G70: 1 | H70: 84.35 | I70: 0 | J70: Facebook | K70: Instapay | L70: Completed | M70: customer113@example.com | N70: 84.35
A71: ORD-0074 | B71: 45864 | C71: Hana Ibrahim | D71: Tanta | E71: USB-C Cable | F71: Electronics | G71: 1 | H71: 117.12 | I71: 5 | J71: WhatsApp | K71: Cash | L71: Completed | M71: customer11@example.com | N71: 111.264
A72: ORD-0075 | B72: 45671 | C72: Sara Mahmoud | D72: Aswan | E72: Backpack | F72: Accessories | G72: 2 | H72: 819.72 | I72: 20 | J72: Store | K72: Instapay | L72: Completed | M72: customer11@example.com | N72: 1311.552
A73: ORD-0076 | B73: 45800 | C73: Ali Mohamed | D73: Mansoura | E73: Keyboard | F73: Electronics | G73: 1 | H73: 690.87 | I73: 15 | J73: WhatsApp | K73: Cash | L73: Completed | M73: customer121@example.com | N73: 587.2395
A74: ORD-0077 | B74: 45711 | C74: Nour Khaled | D74: Mansoura | E74: Desk Lamp | F74: Home & Kitchen | G74: 1 | H74: 411.71 | I74: 15 | J74: WhatsApp | K74: Instapay | L74: Cancelled | M74: customer103@example.com | N74: 349.9535
A75: ORD-0078 | B75: 45787 | C75: Mona Ali | D75: Mansoura | E75: Pen Set | F75: Stationery | G75: 1 | H75: 82.98 | I75: 20 | J75: Store | K75: Vodafone Cash | L75: Completed | M75: customer106@example.com | N75: 66.384
A76: ORD-0080 | B76: 45780 | C76: Youssef Adel | D76: Tanta | E76: Phone Stand | F76: Accessories | G76: 1 | H76: 171.49 | I76: 0 | J76: WhatsApp | K76: Cash | L76: Completed | M76: customer58@example.com | N76: 171.49
A77: ORD-0081 | B77: 45736 | C77: Youssef Adel | D77: Tanta | E77: USB-C Cable | F77: Electronics | G77: 1 | H77: 111.52 | I77: 15 | J77: Facebook | K77: Vodafone Cash | L77: Returned | M77: customer124@example.com | N77: 94.792
A78: ORD-0082 | B78: 45854 | C78: Ali Mohamed | D78: Tanta | E78: Phone Stand | F78: Accessories | G78: 1 | H78: 155.67 | I78: 15 | J78: Online | K78: Cash | L78: Completed | M78: customer71@example.com | N78: 132.3195
A79: ORD-0083 | B79: 45794 | C79: Youssef Adel | D79: Aswan | E79: Backpack | F79: Accessories | G79: 1 | H79: 855.6 | I79: 0 | J79: Online | K79: Credit Card | L79: Completed | M79: customer115@example.com | N79: 855.6
A80: ORD-0084 | B80: 45851 | C80: Nour Khaled | D80: Alexandria | E80: Pen Set | F80: Stationery | G80: 2 | H80: 88.48 | I80: 15 | J80: Online | K80: Vodafone Cash | L80: Returned | M80: customer60@example.com | N80: 150.416
... A317: ORD-0331 | B317: 45926 | C317: Ahmed Hassan | D317: Alexandria | E317: Pen Set | F317: Stationery | G317: 1 | H317: 98.56 | I317: 0 | J317: Online | K317: Cash | L317: Cancelled | M317: customer64@example.com | N317: 98.56
A318: ORD-0332 | B318: not available | C318: Nour Khaled | D318: Mansoura | E318: Wireless Mouse | F318: Electronics | G318: 1 | H318: 395.33 | I318: 10 | J318: WhatsApp | K318: Cash | L318: Completed | M318: customer8@example.com | N318: 355.797
A319: ORD-0333 | B319: 45748 | C319: Ali Mohamed | D319: Tanta | E319: Water Bottle | F319: Home & Kitchen | G319: 1 | H319: 188.73 | I319: 0 | J319: Facebook | K319: Credit Card | L319: Returned | M319: customer67@example.com | N319: 188.73
A320: ORD-0334 | B320: 45741 | C320: Sara Mahmoud | D320: Alexandria | E320: USB-C Cable | F320: Electronics | G320: 1 | H320: 119.6 | I320: 15 | J320: Online | K320: Credit Card | L320: Cancelled | M320: Unknown | N320: 101.66
A321: ORD-0335 | B321: 45662 | C321: Omar Samir | D321: Unknown | E321: Backpack | F321: Accessories | G321: 2 | H321: 870.6 | I321: 0 | J321: Store | K321: Credit Card | L321: Returned | M321: customer65@example.com | N321: 1741.2
A322: ORD-0336 | B322: 45798 | C322: Salma Mostafa | D322: Giza | E322: Headphones | F322: Electronics | G322: 3 | H322: 927.55 | I322: 5 | J322: Facebook | K322: Credit Card | L322: Returned | M322: customer120@example.com | N322: 2643.5175
A323: ORD-0337 | B323: 45861 | C323: Mona Ali | D323: Cairo | E323: Notebook | F323: Stationery | G323: 2 | H323: 60.83 | I323: 10 | J323: Facebook | K323: Instapay | L323: Cancelled | M323: customer77@example.com | N323: 109.494
A324: ORD-0338 | B324: 45799 | C324: Youssef Adel | D324: Giza | E324: USB-C Cable | F324: Electronics | G324: 2 | H324: 118.09 | I324: 15 | J324: Facebook | K324: Credit Card | L324: Completed | M324: customer39@example.com | N324: 200.753
A325: ORD-0339 | B325: 45864 | C325: Omar Samir | D325: Unknown | E325: Pen Set | F325: Stationery | G325: 3 | H325: 87.94 | I325: 0 | J325: WhatsApp | K325: Instapay | L325: Completed | M325: customer67@example.com | N325: 263.82
A326: ORD-0340 | B326: not available | C326: Sara Mahmoud | D326: Aswan | E326: Backpack | F326: Accessories | G326: 1 | H326: 845.66 | I326: 10 | J326: WhatsApp | K326: Instapay | L326: Completed | M326: customer130@example.com | N326: 761.094
A327: ORD-0341 | B327: 45750 | C327: Mona Ali | D327: Mansoura | E327: Notebook | F327: Stationery | G327: 3 | H327: 61.06 | I327: 0 | J327: Facebook | K327: Credit Card | L327: Completed | M327: customer86@example.com | N327: 183.18
A328: ORD-0342 | B328: 45815 | C328: Nour Khaled | D328: Giza | E328: USB-C Cable | F328: Electronics | G328: 1 | H328: 114.7 | I328: 0 | J328: Facebook | K328: Vodafone Cash | L328: Returned | M328: customer31@example.com | N328: 114.7
A329: ORD-0343 | B329: 45694 | C329: Sara Mahmoud | D329: Tanta | E329: Phone Stand | F329: Accessories | G329: 1 | H329: 158.79 | I329: 0 | J329: WhatsApp | K329: Instapay | L329: Cancelled | M329: customer106@example.com | N329: 158.79
...

Sheet Cleaning_Notes
A1: Item | B1: What was done / what you need to know
A2: Original data | B2: The original Orders_Raw sheet is preserved unchanged.
A3: Cleaned data | B3: Use the Cleaned_Data sheet as the source for your PivotTables.
A4: Header | B4: Renamed the sixth column from '=Av' to 'Category'.
A5: City labels | B5: Trimmed extra spaces and standardized capitalization (e.g. Cairo, Alexandria). 'Unknown' was retained.
A6: Sales channels | B6: Standardized capitalization and spacing (e.g. online -> Online; Whatsapp -> WhatsApp).
A7: Order statuses | B7: Standardized capitalization and spacing (e.g. cancelled -> Cancelled; returned -> Returned).
A8: Dates | B8: Converted valid YYYY-MM-DD text values to Excel date values.
A9: Unit price in source H6 | B9: The source contained the text '=AVERAGE(H94,H227)'. In Cleaned_Data, this was converted to its numeric result (127.005) using the referenced values H94=122.14 and H227=131.87.
A10: Net sales | B10: Added Net_Sales_EGP = Quantity * Unit_Price_EGP * (1 - Discount_% / 100). This is calculated for every row, including non-completed statuses; use the Order_Status filter = Completed when analyzing completed sales.
A11: Unknown city/email | B11: Values labelled 'Unknown' were retained rather than guessed or replaced.
A12: Record-count discrepancy | B12: The provided file has 335 non-empty data rows, but Project_Guide says 354 records. No missing records were invented. Please ask your teammate/instructor whether 19 records were intentionally excluded or whether a fuller file exists.
... A14: Important | B14: Review the record-count discrepancy before treating the analysis as final. The cleaned sheet fixes formatting/label issues but does not invent missing source records.
